Files already downloaded and verified
Files already downloaded and verified
Files already downloaded and verified
Files already downloaded and verified
[Train epoch] 1:   0%|          | 0/391 [00:00<?, ?it/s]Traceback (most recent call last):
  File "main.py", line 187, in <module>
    trainer.train(train_loader, val_loader)
  File "main.py", line 152, in train
    avg_loss = self.train_one_epoch(epoch+1, train_loader)
  File "main.py", line 56, in train_one_epoch
    for batch in data_loader:
  File "/usr/local/lib/python3.8/dist-packages/torch/utils/data/dataloader.py", line 363, in __next__
    data = self._next_data()
  File "/usr/local/lib/python3.8/dist-packages/torch/utils/data/dataloader.py", line 989, in _next_data
    return self._process_data(data)
  File "/usr/local/lib/python3.8/dist-packages/torch/utils/data/dataloader.py", line 1014, in _process_data
    data.reraise()
  File "/usr/local/lib/python3.8/dist-packages/torch/_utils.py", line 395, in reraise
    raise self.exc_type(msg)
KeyError: Caught KeyError in DataLoader worker process 0.
Original Traceback (most recent call last):
  File "/usr/local/lib/python3.8/dist-packages/torch/utils/data/_utils/worker.py", line 185, in _worker_loop
    data = fetcher.fetch(index)
  File "/usr/local/lib/python3.8/dist-packages/torch/utils/data/_utils/fetch.py", line 47, in fetch
    return self.collate_fn(data)
  File "main.py", line 20, in collate_fn
    in_size = data[0][0].size()
KeyError: 0

